# 在程序运行的过程中，如果发生了错误，可以事先约定返回一个错误代码，这样，就可以知道是否有错，以及出错的原因。在操作系统提供的调用中，返回错误码非常常见。比如打开文件的函数open()，成功时返回文件描述符（就是一个整数），出错时返回-1。
# 用错误码来表示是否出错十分不便，因为函数本身应该返回的正常结果和错误码混在一起，造成调用者必须用大量的代码来判断是否出错：

def foo():
    r = some_function()
    if r == (-1):
        return (-1)
    return r


def bar():
    r = foo()
    if r == (-1):
        print('Error')
    else:
        pass


# 一旦出错，还要一级一级上报，直到某个函数可以处理该错误（比如，给用户输出一个错误信息）。
# 所以高级语言通常都内置了一套try...except...finally...的错误处理机制，Python也不例外。
# try
# 让我们用一个例子来看看try的机制：
try:
    print('try...')
    r = 10 / 0
    print('result:', r)
except ZeroDivisionError as e:
    print('except:', e)
finally:
    print('finally...')
print('End')

'''
当我们认为某些代码可能会出错时，就可以用try来运行这段代码，如果执行出错，则后续代码不会继续执行，而是直接跳转至错误处理代码，即except语句块，执行完except后，如果有finally语句块，则执行finally语句块，至此，执行完毕。
'''
# 上面的代码在计算10 / 0时会产生一个除法运算错误：
# try...
# except: division by zero
# finally...
# END
# 从输出可以看到，当错误发生时，后续语句print('result:', r)不会被执行，except由于捕获到ZeroDivisionError，因此被执行。最后，finally语句被执行。然后，程序继续按照流程往下走。
#
# 如果把除数0改成2，则执行结果如下：
# try...
# result: 5
# finally...
# END
# 由于没有错误发生，所以except语句块不会被执行，但是finally如果有，则一定会被执行（可以没有finally语句）。
# 你还可以猜测，错误应该有很多种类，如果发生了不同类型的错误，应该由不同的except语句块处理。没错，可以有多个except来捕获不同类型的错误：
try:
    print('try...')
    r = 10 / int('a')
    print('result:', r)
except ValueError as e:
    print('ValueError:', e)
except ZeroDivisionError as e:
    print('ZeroDivisionError:', e)
finally:
    print('finally...')
print('End')

# 如果没有错误发生，可以在except语句块后面加一个else，当没有错误发生时，会自动执行else语句：

try:
    print('try...')
    r = 10 / int('2')
    print('result:', r)
except ValueError as e:
    print('ValueError:', e)
except ZeroDivisionError as e:
    print('ZeroDivisionError:', e)
else:
    print('no error!')
finally:
    print('finally...')
print('End')

'''
Python所有的错误都是从BaseException类派生的，常见的错误类型和继承关系看这里：

BaseException
 +-- SystemExit
 +-- KeyboardInterrupt
 +-- GeneratorExit
 +-- Exception
      +-- StopIteration
      +-- StopAsyncIteration
      +-- ArithmeticError
      |    +-- FloatingPointError
      |    +-- OverflowError
      |    +-- ZeroDivisionError
      +-- AssertionError
      +-- AttributeError
      +-- BufferError
      +-- EOFError
      +-- ImportError
      +-- LookupError
      |    +-- IndexError
      |    +-- KeyError
      +-- MemoryError
      +-- NameError
      |    +-- UnboundLocalError
      +-- OSError
      |    +-- BlockingIOError
      |    +-- ChildProcessError
      |    +-- ConnectionError
      |    |    +-- BrokenPipeError
      |    |    +-- ConnectionAbortedError
      |    |    +-- ConnectionRefusedError
      |    |    +-- ConnectionResetError
      |    +-- FileExistsError
      |    +-- FileNotFoundError
      |    +-- InterruptedError
      |    +-- IsADirectoryError
      |    +-- NotADirectoryError
      |    +-- PermissionError
      |    +-- ProcessLookupError
      |    +-- TimeoutError
      +-- ReferenceError
      +-- RuntimeError
      |    +-- NotImplementedError
      |    +-- RecursionError
      +-- SyntaxError
      |    +-- IndentationError
      |         +-- TabError
      +-- SystemError
      +-- TypeError
      +-- ValueError
      |    +-- UnicodeError
      |         +-- UnicodeDecodeError
      |         +-- UnicodeEncodeError
      |         +-- UnicodeTranslateError
      +-- Warning
           +-- DeprecationWarning
           +-- PendingDeprecationWarning
           +-- RuntimeWarning
           +-- SyntaxWarning
           +-- UserWarning
           +-- FutureWarning
           +-- ImportWarning
           +-- UnicodeWarning
           +-- BytesWarning
           +-- ResourceWarning
'''
print('=======================')
'''
使用try...except捕获错误还有一个巨大的好处，就是可以跨越多层调用，比如函数main()调用foo()，foo()调用bar()，结果bar()出错了，这时，只要main()捕获到了，就可以处理：
'''


def foo(s):
    return 10 / int(s)


def bar(s):
    return foo(s) * 2


def main():
    try:
        bar('0')
    except Exception as e:
        print('Error:', e)
    finally:
        print('finally...')


main()

'''
def main():
	bar('0')
main()

记录错误

如果不捕获错误，自然可以让Python解释器来打印出错误堆栈，但程序也被结束了。
既然我们能捕获错误，就可以把错误堆栈打印出来，然后分析错误原因，同时，让程序继续执行下去。

Python内置的logging模块可以非常容易地记录错误信息：
通过配置，logging还可以把错误记录到日志文件里，方便事后排查。
'''
import logging


def foo(s):
    return 10 / int(s)


def bar(s):
    return foo(s) * 2


def main():
    try:
        bar('0')
    except Exception as e:
        logging.exception(e)


main()

print()
print('-----')

'''
抛出错误

因为错误是class，捕获一个错误就是捕获到该class的一个实例。
因此，错误并不是凭空产生的，而是有意创建并抛出的。Python的内置函数会抛出很多类型的错误，我们自己编写的函数也可以抛出错误。

如果要抛出错误，首先根据需要，可以定义一个错误的class，选择好继承关系，然后，用raise语句抛出一个错误的实例：
'''


class FooError(ValueError):
    pass


def foo(s):
    n = int(s)
    if n == 0:
        raise FooError('invalid value:%s' % s)
    return 10 / s


foo('0')
# 执行，可以最后跟踪到我们自己定义的错误：
#
# $ python3 err_raise.py
# Traceback (most recent call last):
#   File "err_throw.py", line 11, in <module>
#     foo('0')
#   File "err_throw.py", line 8, in foo
#     raise FooError('invalid value: %s' % s)
# __main__.FooError: invalid value: 0
# 只有在必要的时候才定义我们自己的错误类型。如果可以选择Python已有的内置的错误类型（比如ValueError，TypeError），尽量使用Python内置的错误类型。
#
# 最后，我们来看另一种错误处理的方式：

# err_reraise.py

def foo(s):
    n = int(s)
    if n==0:
        raise ValueError('invalid value: %s' % s)
    return 10 / n

def bar():
    try:
        foo('0')
    except ValueError as e:
        print('ValueError!')
        raise

bar()
# 在bar()函数中，我们明明已经捕获了错误，但是，打印一个ValueError!后，又把错误通过raise语句抛出去了，这不有病么？
#
# 其实这种错误处理方式不但没病，而且相当常见。捕获错误目的只是记录一下，便于后续追踪。
# 但是，由于当前函数不知道应该怎么处理该错误，所以，最恰当的方式是继续往上抛，让顶层调用者去处理。
# 好比一个员工处理不了一个问题时，就把问题抛给他的老板，如果他的老板也处理不了，就一直往上抛，最终会抛给CEO去处理。
#
# raise语句如果不带参数，就会把当前错误原样抛出。此外，在except中raise一个Error，还可以把一种类型的错误转化成另一种类型：

try:
    10 / 0
except ZeroDivisionError:
    raise ValueError('input error!')
# 只要是合理的转换逻辑就可以，但是，决不应该把一个IOError转换成毫不相干的ValueError
